{
 "cells": [
  {
   "cell_type": "code",
   "execution_count": 1,
   "metadata": {},
   "outputs": [
    {
     "ename": "ImportError",
     "evalue": "cannot import name 'view' from 'spyre' (/opt/anaconda3/lib/python3.12/site-packages/spyre/__init__.py)",
     "output_type": "error",
     "traceback": [
      "\u001b[0;31m---------------------------------------------------------------------------\u001b[0m",
      "\u001b[0;31mModuleNotFoundError\u001b[0m                       Traceback (most recent call last)",
      "File \u001b[0;32m/opt/anaconda3/lib/python3.12/site-packages/spyre/server.py:28\u001b[0m\n\u001b[1;32m     27\u001b[0m \u001b[38;5;28;01mtry\u001b[39;00m:\n\u001b[0;32m---> 28\u001b[0m     \u001b[38;5;28;01mfrom\u001b[39;00m \u001b[38;5;21;01m.\u001b[39;00m \u001b[38;5;28;01mimport\u001b[39;00m View\n\u001b[1;32m     29\u001b[0m \u001b[38;5;28;01mexcept\u001b[39;00m \u001b[38;5;167;01mException\u001b[39;00m:\n",
      "File \u001b[0;32m/opt/anaconda3/lib/python3.12/site-packages/spyre/View.py:7\u001b[0m\n\u001b[1;32m      6\u001b[0m \u001b[38;5;28;01mimport\u001b[39;00m \u001b[38;5;21;01mio\u001b[39;00m\n\u001b[0;32m----> 7\u001b[0m \u001b[38;5;28;01mfrom\u001b[39;00m \u001b[38;5;21;01mimp\u001b[39;00m \u001b[38;5;28;01mimport\u001b[39;00m reload\n\u001b[1;32m      8\u001b[0m reload(sys)\n",
      "\u001b[0;31mModuleNotFoundError\u001b[0m: No module named 'imp'",
      "\nDuring handling of the above exception, another exception occurred:\n",
      "\u001b[0;31mModuleNotFoundError\u001b[0m                       Traceback (most recent call last)",
      "File \u001b[0;32m/opt/anaconda3/lib/python3.12/site-packages/spyre/server.py:31\u001b[0m\n\u001b[1;32m     30\u001b[0m \u001b[38;5;28;01mtry\u001b[39;00m:\n\u001b[0;32m---> 31\u001b[0m     \u001b[38;5;28;01mimport\u001b[39;00m \u001b[38;5;21;01mView\u001b[39;00m\n\u001b[1;32m     32\u001b[0m \u001b[38;5;28;01mexcept\u001b[39;00m \u001b[38;5;167;01mException\u001b[39;00m:\n",
      "\u001b[0;31mModuleNotFoundError\u001b[0m: No module named 'View'",
      "\nDuring handling of the above exception, another exception occurred:\n",
      "\u001b[0;31mImportError\u001b[0m                               Traceback (most recent call last)",
      "Cell \u001b[0;32mIn[1], line 1\u001b[0m\n\u001b[0;32m----> 1\u001b[0m \u001b[38;5;28;01mfrom\u001b[39;00m \u001b[38;5;21;01mspyre\u001b[39;00m \u001b[38;5;28;01mimport\u001b[39;00m server\n",
      "File \u001b[0;32m/opt/anaconda3/lib/python3.12/site-packages/spyre/server.py:33\u001b[0m\n\u001b[1;32m     31\u001b[0m         \u001b[38;5;28;01mimport\u001b[39;00m \u001b[38;5;21;01mView\u001b[39;00m\n\u001b[1;32m     32\u001b[0m     \u001b[38;5;28;01mexcept\u001b[39;00m \u001b[38;5;167;01mException\u001b[39;00m:\n\u001b[0;32m---> 33\u001b[0m         \u001b[38;5;28;01mfrom\u001b[39;00m \u001b[38;5;21;01m.\u001b[39;00m \u001b[38;5;28;01mimport\u001b[39;00m view \u001b[38;5;28;01mas\u001b[39;00m View\n\u001b[1;32m     35\u001b[0m \u001b[38;5;66;03m# Settings\u001b[39;00m\n\u001b[1;32m     36\u001b[0m include_df_index \u001b[38;5;241m=\u001b[39m \u001b[38;5;28;01mFalse\u001b[39;00m\n",
      "\u001b[0;31mImportError\u001b[0m: cannot import name 'view' from 'spyre' (/opt/anaconda3/lib/python3.12/site-packages/spyre/__init__.py)"
     ]
    }
   ],
   "source": [
    "from spyre import server"
   ]
  }
 ],
 "metadata": {
  "kernelspec": {
   "display_name": "base",
   "language": "python",
   "name": "python3"
  },
  "language_info": {
   "codemirror_mode": {
    "name": "ipython",
    "version": 3
   },
   "file_extension": ".py",
   "mimetype": "text/x-python",
   "name": "python",
   "nbconvert_exporter": "python",
   "pygments_lexer": "ipython3",
   "version": "3.12.2"
  }
 },
 "nbformat": 4,
 "nbformat_minor": 2
}
